Workbook

Sheet Master list
B1: Updated data | C1: 43868
A2: STT | B2: ScName | C2: Tên nhà thuốc | D2: Số điện thoại | E2: Địa chỉ | F2: Bài 1 | G2: Bài 2 | H2: Bài 3 | I2: Bài 4 | J2: Results | K2: Khu vuc | L2: ASM | M2: comment | N2: Count of Results | O2: ASM | U2: Count of Results
A3: 1 | B3: Phan Thi Thu Dong | C3: bao chau | D3: 0908770719 | E3: 436, P.08,Quận 10,Hồ Chí Minh | F3: =IFERROR(VLOOKUP(D3,[3]Bai1_VuotQua!$D$8:$I$143,6,FALSE),"NY") -> NY | G3: =IFERROR(VLOOKUP(D3,[3]Bai2_VuotQua!$D$8:$I$120,6,FALSE),"NY") -> NY | H3: =IFERROR(VLOOKUP(D3,[3]Bai3_VuotQua!$D$8:$I$122,6,FALSE),"NY") -> NY | I3: =IFERROR(VLOOKUP(D3,[3]Bai4_VuotQua!$D$8:$I$117,6,FALSE),"NY") -> NY | J3: =IF(AND(F3="done",G3="done",H3="done",I3="done"),"done all",IF(OR(AND(F3="done",G3="done",H3="done"),AND(F3="done",G3="done",I3="done"),AND(F3="done",H3="done",I3="done"),AND(G3="done",H3="done",I3="done")),"done 3 lession",IF(OR(AND(F3="done",G3="done"),AND(F3="done",H3="done"),AND(F3="done",I3="done"),AND(G3="done",H3="done"),AND(G3="done",I3="done"),AND(H3="done",I3="done")),"done 2 lession",IF(OR(F3="done",G3="done",H3="done",I3="done"),"done 1 lession","NY")))) -> NY | K3: =VLOOKUP($D3,[1]Bai1_View!$E$2:$J$177,5,FALSE) -> HCM | L3: =VLOOKUP($D3,[1]Bai1_View!$E$2:$J$177,6,FALSE) -> A. Tri | M3: =IFERROR(VLOOKUP(D3,[2]Hồng!$D$1:$M$21,10,FALSE),0) -> 0 | N3: Results | O3: A. Tuan | P3: A. Tho | Q3: A. Tri | R3: C. Quy | S3: Grand Total | U3: ASM | V3: Results | W3: Khu vuc | X3: Total
A4: 2 | B4: Nguyễn thị thắm | C4: nhà thuốc hải đăng | D4: 0982819628 | E4: 142 vũ trọng phụng, P.Nhân Chính,Thanh Xuân,Hà Nội | F4: =IFERROR(VLOOKUP(D4,[3]Bai1_VuotQua!$D$8:$I$143,6,FALSE),"NY") -> done | G4: =IFERROR(VLOOKUP(D4,[3]Bai2_VuotQua!$D$8:$I$120,6,FALSE),"NY") -> NY | H4: =IFERROR(VLOOKUP(D4,[3]Bai3_VuotQua!$D$8:$I$122,6,FALSE),"NY") -> NY | I4: =IFERROR(VLOOKUP(D4,[3]Bai4_VuotQua!$D$8:$I$117,6,FALSE),"NY") -> NY | J4: =IF(AND(F4="done",G4="done",H4="done",I4="done"),"done all",IF(OR(AND(F4="done",G4="done",H4="done"),AND(F4="done",G4="done",I4="done"),AND(F4="done",H4="done",I4="done"),AND(G4="done",H4="done",I4="done")),"done 3 lession",IF(OR(AND(F4="done",G4="done"),AND(F4="done",H4="done"),AND(F4="done",I4="done"),AND(G4="done",H4="done"),AND(G4="done",I4="done"),AND(H4="done",I4="done")),"done 2 lession",IF(OR(F4="done",G4="done",H4="done",I4="done"),"done 1 lession","NY")))) -> done 1 lession | K4: HN | L4: C. Quy | M4: =IFERROR(VLOOKUP(D4,[2]Hồng!$D$1:$M$21,10,FALSE),0) -> 0 | N4: done 1 lession | O4: 2 | P4: 14 | Q4: 9 | R4: 14 | S4: 39 | U4: A. Tuan | V4: done 1 lession | W4: Da Nang | X4: 1
A5: 3 | B5: Uong Thi Hoang Oanh | C5: NHA THUOC MINH TAM | D5: 0908555420 | E5: 475 BA HAT, P.08,Quận 10,Hồ Chí Minh | F5: =IFERROR(VLOOKUP(D5,[3]Bai1_VuotQua!$D$8:$I$143,6,FALSE),"NY") -> NY | G5: =IFERROR(VLOOKUP(D5,[3]Bai2_VuotQua!$D$8:$I$120,6,FALSE),"NY") -> NY | H5: =IFERROR(VLOOKUP(D5,[3]Bai3_VuotQua!$D$8:$I$122,6,FALSE),"NY") -> NY | I5: =IFERROR(VLOOKUP(D5,[3]Bai4_VuotQua!$D$8:$I$117,6,FALSE),"NY") -> NY | J5: =IF(AND(F5="done",G5="done",H5="done",I5="done"),"done all",IF(OR(AND(F5="done",G5="done",H5="done"),AND(F5="done",G5="done",I5="done"),AND(F5="done",H5="done",I5="done"),AND(G5="done",H5="done",I5="done")),"done 3 lession",IF(OR(AND(F5="done",G5="done"),AND(F5="done",H5="done"),AND(F5="done",I5="done"),AND(G5="done",H5="done"),AND(G5="done",I5="done"),AND(H5="done",I5="done")),"done 2 lession",IF(OR(F5="done",G5="done",H5="done",I5="done"),"done 1 lession","NY")))) -> NY | K5: =VLOOKUP($D5,[1]Bai1_View!$E$2:$J$177,5,FALSE) -> HCM | L5: =VLOOKUP($D5,[1]Bai1_View!$E$2:$J$177,6,FALSE) -> A. Tri | M5: =IFERROR(VLOOKUP(D5,[2]Hồng!$D$1:$M$21,10,FALSE),0) -> 0 | N5: done 2 lession | P5: 5 | Q5: 4 | R5: 6 | S5: 15 | W5: Thanh Hoa | X5: 1
A6: 4 | B6: Nguyễn văn lợi | C6: nhà thuốc hữu nghị | D6: 0384880866 | E6: 174 hạ đình, P.Thanh Xuân Trung,Thanh Xuân,Hà Nội | F6: =IFERROR(VLOOKUP(D6,[3]Bai1_VuotQua!$D$8:$I$143,6,FALSE),"NY") -> NY | G6: =IFERROR(VLOOKUP(D6,[3]Bai2_VuotQua!$D$8:$I$120,6,FALSE),"NY") -> NY | H6: =IFERROR(VLOOKUP(D6,[3]Bai3_VuotQua!$D$8:$I$122,6,FALSE),"NY") -> NY | I6: =IFERROR(VLOOKUP(D6,[3]Bai4_VuotQua!$D$8:$I$117,6,FALSE),"NY") -> NY | J6: =IF(AND(F6="done",G6="done",H6="done",I6="done"),"done all",IF(OR(AND(F6="done",G6="done",H6="done"),AND(F6="done",G6="done",I6="done"),AND(F6="done",H6="done",I6="done"),AND(G6="done",H6="done",I6="done")),"done 3 lession",IF(OR(AND(F6="done",G6="done"),AND(F6="done",H6="done"),AND(F6="done",I6="done"),AND(G6="done",H6="done"),AND(G6="done",I6="done"),AND(H6="done",I6="done")),"done 2 lession",IF(OR(F6="done",G6="done",H6="done",I6="done"),"done 1 lession","NY")))) -> NY | K6: HN | L6: C. Quy | M6: =IFERROR(VLOOKUP(D6,[2]Hồng!$D$1:$M$21,10,FALSE),0) -> 0 | N6: done 3 lession | P6: 6 | Q6: 4 | R6: 5 | S6: 15 | V6: NY | W6: Da Nang | X6: 1
A7: 5 | B7: Vũ Thị Diên | C7: NT Thái Hà | D7: 0906012898 | E7: 86 Lò Đúc, P.Phạm Đình Hổ,Hai Bà Trưng,Hà Nội | F7: =IFERROR(VLOOKUP(D7,[3]Bai1_VuotQua!$D$8:$I$143,6,FALSE),"NY") -> done | G7: =IFERROR(VLOOKUP(D7,[3]Bai2_VuotQua!$D$8:$I$120,6,FALSE),"NY") -> NY | H7: =IFERROR(VLOOKUP(D7,[3]Bai3_VuotQua!$D$8:$I$122,6,FALSE),"NY") -> NY | I7: =IFERROR(VLOOKUP(D7,[3]Bai4_VuotQua!$D$8:$I$117,6,FALSE),"NY") -> NY | J7: =IF(AND(F7="done",G7="done",H7="done",I7="done"),"done all",IF(OR(AND(F7="done",G7="done",H7="done"),AND(F7="done",G7="done",I7="done"),AND(F7="done",H7="done",I7="done"),AND(G7="done",H7="done",I7="done")),"done 3 lession",IF(OR(AND(F7="done",G7="done"),AND(F7="done",H7="done"),AND(F7="done",I7="done"),AND(G7="done",H7="done"),AND(G7="done",I7="done"),AND(H7="done",I7="done")),"done 2 lession",IF(OR(F7="done",G7="done",H7="done",I7="done"),"done 1 lession","NY")))) -> done 1 lession | K7: =VLOOKUP($D7,[1]Bai1_View!$E$2:$J$177,5,FALSE) -> HN | L7: =VLOOKUP($D7,[1]Bai1_View!$E$2:$J$177,6,FALSE) -> C. Quy | M7: =IFERROR(VLOOKUP(D7,[2]Hồng!$D$1:$M$21,10,FALSE),0) -> 0 | N7: done all | P7: 35 | Q7: 17 | R7: 40 | S7: 92 | W7: Ha Tinh | X7: 1
A8: 6 | B8: nguyen thi thu hien | C8: nha thuoc huong dung | D8: 0352494097 | E8: 72a/5 ph9 phuong tan bien, P.Tân Biên,Biên Hòa,Đồng Nai | F8: =IFERROR(VLOOKUP(D8,[3]Bai1_VuotQua!$D$8:$I$143,6,FALSE),"NY") -> done | G8: =IFERROR(VLOOKUP(D8,[3]Bai2_VuotQua!$D$8:$I$120,6,FALSE),"NY") -> NY | H8: =IFERROR(VLOOKUP(D8,[3]Bai3_VuotQua!$D$8:$I$122,6,FALSE),"NY") -> NY | I8: =IFERROR(VLOOKUP(D8,[3]Bai4_VuotQua!$D$8:$I$117,6,FALSE),"NY") -> NY | J8: =IF(AND(F8="done",G8="done",H8="done",I8="done"),"done all",IF(OR(AND(F8="done",G8="done",H8="done"),AND(F8="done",G8="done",I8="done"),AND(F8="done",H8="done",I8="done"),AND(G8="done",H8="done",I8="done")),"done 3 lession",IF(OR(AND(F8="done",G8="done"),AND(F8="done",H8="done"),AND(F8="done",I8="done"),AND(G8="done",H8="done"),AND(G8="done",I8="done"),AND(H8="done",I8="done")),"done 2 lession",IF(OR(F8="done",G8="done",H8="done",I8="done"),"done 1 lession","NY")))) -> done 1 lession | K8: =VLOOKUP($D8,[1]Bai1_View!$E$2:$J$177,5,FALSE) -> Đồng Nai | L8: =VLOOKUP($D8,[1]Bai1_View!$E$2:$J$177,6,FALSE) -> A. Tho | M8: =IFERROR(VLOOKUP(D8,[2]Hồng!$D$1:$M$21,10,FALSE),0) -> 0 | N8: NY | O8: 9 | P8: 24 | Q8: 45 | R8: 43 | S8: 121 | W8: Hải Phòng | X8: 1
A9: 7 | B9: Nguyen anh phuong | C9: nt an huy so 8 | D9: 0356952959 | E9: Khu do thi thanh thai, P.Dịch Vọng,Cầu Giấy,Hà Nội | F9: =IFERROR(VLOOKUP(D9,[3]Bai1_VuotQua!$D$8:$I$143,6,FALSE),"NY") -> NY | G9: =IFERROR(VLOOKUP(D9,[3]Bai2_VuotQua!$D$8:$I$120,6,FALSE),"NY") -> NY | H9: =IFERROR(VLOOKUP(D9,[3]Bai3_VuotQua!$D$8:$I$122,6,FALSE),"NY") -> done | I9: =IFERROR(VLOOKUP(D9,[3]Bai4_VuotQua!$D$8:$I$117,6,FALSE),"NY") -> NY | J9: =IF(AND(F9="done",G9="done",H9="done",I9="done"),"done all",IF(OR(AND(F9="done",G9="done",H9="done"),AND(F9="done",G9="done",I9="done"),AND(F9="done",H9="done",I9="done"),AND(G9="done",H9="done",I9="done")),"done 3 lession",IF(OR(AND(F9="done",G9="done"),AND(F9="done",H9="done"),AND(F9="done",I9="done"),AND(G9="done",H9="done"),AND(G9="done",I9="done"),AND(H9="done",I9="done")),"done 2 lession",IF(OR(F9="done",G9="done",H9="done",I9="done"),"done 1 lession","NY")))) -> done 1 lession | K9: HN | L9: C. Quy | M9: =IFERROR(VLOOKUP(D9,[2]Hồng!$D$1:$M$21,10,FALSE),0) -> 0 | N9: Grand Total | O9: 11 | P9: 84 | Q9: 79 | R9: 108 | S9: 282 | W9: Nghệ An | X9: 3
A10: 8 | B10: Nguyễn thị trang | C10: nhà thuốc hồ anh tuấn | D10: 0859363616 | E10: Tầng 1 - 17T4 trung hoà, P.Nhân Chính,Thanh Xuân,Hà Nội | F10: =IFERROR(VLOOKUP(D10,[3]Bai1_VuotQua!$D$8:$I$143,6,FALSE),"NY") -> NY | G10: =IFERROR(VLOOKUP(D10,[3]Bai2_VuotQua!$D$8:$I$120,6,FALSE),"NY") -> NY | H10: =IFERROR(VLOOKUP(D10,[3]Bai3_VuotQua!$D$8:$I$122,6,FALSE),"NY") -> NY | I10: =IFERROR(VLOOKUP(D10,[3]Bai4_VuotQua!$D$8:$I$117,6,FALSE),"NY") -> NY | J10: =IF(AND(F10="done",G10="done",H10="done",I10="done"),"done all",IF(OR(AND(F10="done",G10="done",H10="done"),AND(F10="done",G10="done",I10="done"),AND(F10="done",H10="done",I10="done"),AND(G10="done",H10="done",I10="done")),"done 3 lession",IF(OR(AND(F10="done",G10="done"),AND(F10="done",H10="done"),AND(F10="done",I10="done"),AND(G10="done",H10="done"),AND(G10="done",I10="done"),AND(H10="done",I10="done")),"done 2 lession",IF(OR(F10="done",G10="done",H10="done",I10="done"),"done 1 lession","NY")))) -> NY | K10: HN | L10: C. Quy | M10: =IFERROR(VLOOKUP(D10,[2]Hồng!$D$1:$M$21,10,FALSE),0) -> 0 | W10: Phú Thọ | X10: 3
A11: 9 | B11: 19339 | C11: nt 110 vinh tuy | D11: 0966046385 | E11: 36hoang cau, P.Ô Chợ Dừa,Đống Đa,Hà Nội | F11: =IFERROR(VLOOKUP(D11,[3]Bai1_VuotQua!$D$8:$I$143,6,FALSE),"NY") -> NY | G11: =IFERROR(VLOOKUP(D11,[3]Bai2_VuotQua!$D$8:$I$120,6,FALSE),"NY") -> NY | H11: =IFERROR(VLOOKUP(D11,[3]Bai3_VuotQua!$D$8:$I$122,6,FALSE),"NY") -> NY | I11: =IFERROR(VLOOKUP(D11,[3]Bai4_VuotQua!$D$8:$I$117,6,FALSE),"NY") -> NY | J11: =IF(AND(F11="done",G11="done",H11="done",I11="done"),"done all",IF(OR(AND(F11="done",G11="done",H11="done"),AND(F11="done",G11="done",I11="done"),AND(F11="done",H11="done",I11="done"),AND(G11="done",H11="done",I11="done")),"done 3 lession",IF(OR(AND(F11="done",G11="done"),AND(F11="done",H11="done"),AND(F11="done",I11="done"),AND(G11="done",H11="done"),AND(G11="done",I11="done"),AND(H11="done",I11="done")),"done 2 lession",IF(OR(F11="done",G11="done",H11="done",I11="done"),"done 1 lession","NY")))) -> NY | K11: HN | L11: C. Quy | M11: =IFERROR(VLOOKUP(D11,[2]Hồng!$D$1:$M$21,10,FALSE),0) -> 0 | U11: A. Tuan Total | X11: 11
A12: 10 | B12: Phan thị Huệ | C12: nhà thuốc Đức cường | D12: 0362225885 | E12: 35 cũ nay 251 Trần Đại Nghĩa, P.Đồng Tâm,Hai Bà Trưng,Hà Nội | F12: =IFERROR(VLOOKUP(D12,[3]Bai1_VuotQua!$D$8:$I$143,6,FALSE),"NY") -> done | G12: =IFERROR(VLOOKUP(D12,[3]Bai2_VuotQua!$D$8:$I$120,6,FALSE),"NY") -> done | H12: =IFERROR(VLOOKUP(D12,[3]Bai3_VuotQua!$D$8:$I$122,6,FALSE),"NY") -> done | I12: =IFERROR(VLOOKUP(D12,[3]Bai4_VuotQua!$D$8:$I$117,6,FALSE),"NY") -> done | J12: =IF(AND(F12="done",G12="done",H12="done",I12="done"),"done all",IF(OR(AND(F12="done",G12="done",H12="done"),AND(F12="done",G12="done",I12="done"),AND(F12="done",H12="done",I12="done"),AND(G12="done",H12="done",I12="done")),"done 3 lession",IF(OR(AND(F12="done",G12="done"),AND(F12="done",H12="done"),AND(F12="done",I12="done"),AND(G12="done",H12="done"),AND(G12="done",I12="done"),AND(H12="done",I12="done")),"done 2 lession",IF(OR(F12="done",G12="done",H12="done",I12="done"),"done 1 lession","NY")))) -> done all | K12: =VLOOKUP($D12,[1]Bai1_View!$E$2:$J$177,5,FALSE) -> HN | L12: =VLOOKUP($D12,[1]Bai1_View!$E$2:$J$177,6,FALSE) -> C. Quy | M12: =IFERROR(VLOOKUP(D12,[2]Hồng!$D$1:$M$21,10,FALSE),0) -> ok | N12: Count of Results | U12: A. Tho | V12: done 1 lession | W12: An Giang | X12: 2
A13: 11 | B13: nguyễn khắc dũng | C13: nhà thuốc minh hồng 2 | D13: 0986891582 | E13: 204 Hoàng Văn Thái, P.Nhân Chính,Thanh Xuân,Hà Nội | F13: =IFERROR(VLOOKUP(D13,[3]Bai1_VuotQua!$D$8:$I$143,6,FALSE),"NY") -> done | G13: =IFERROR(VLOOKUP(D13,[3]Bai2_VuotQua!$D$8:$I$120,6,FALSE),"NY") -> NY | H13: =IFERROR(VLOOKUP(D13,[3]Bai3_VuotQua!$D$8:$I$122,6,FALSE),"NY") -> NY | I13: =IFERROR(VLOOKUP(D13,[3]Bai4_VuotQua!$D$8:$I$117,6,FALSE),"NY") -> done | J13: =IF(AND(F13="done",G13="done",H13="done",I13="done"),"done all",IF(OR(AND(F13="done",G13="done",H13="done"),AND(F13="done",G13="done",I13="done"),AND(F13="done",H13="done",I13="done"),AND(G13="done",H13="done",I13="done")),"done 3 lession",IF(OR(AND(F13="done",G13="done"),AND(F13="done",H13="done"),AND(F13="done",I13="done"),AND(G13="done",H13="done"),AND(G13="done",I13="done"),AND(H13="done",I13="done")),"done 2 lession",IF(OR(F13="done",G13="done",H13="done",I13="done"),"done 1 lession","NY")))) -> done 2 lession | K13: HN | L13: C. Quy | M13: =IFERROR(VLOOKUP(D13,[2]Hồng!$D$1:$M$21,10,FALSE),0) -> 0 | N13: Results | O13: Total | W13: Bình Dương | X13: 1
A14: 12 | B14: Lê Thu Hà | C14: NT Ngân Hà | D14: 0937234829 | E14: Cong quynh, P.Phạm Ngũ Lão,Quận 1,Hồ Chí Minh | F14: =IFERROR(VLOOKUP(D14,[3]Bai1_VuotQua!$D$8:$I$143,6,FALSE),"NY") -> done | G14: =IFERROR(VLOOKUP(D14,[3]Bai2_VuotQua!$D$8:$I$120,6,FALSE),"NY") -> done | H14: =IFERROR(VLOOKUP(D14,[3]Bai3_VuotQua!$D$8:$I$122,6,FALSE),"NY") -> done | I14: =IFERROR(VLOOKUP(D14,[3]Bai4_VuotQua!$D$8:$I$117,6,FALSE),"NY") -> done | J14: =IF(AND(F14="done",G14="done",H14="done",I14="done"),"done all",IF(OR(AND(F14="done",G14="done",H14="done"),AND(F14="done",G14="done",I14="done"),AND(F14="done",H14="done",I14="done"),AND(G14="done",H14="done",I14="done")),"done 3 lession",IF(OR(AND(F14="done",G14="done"),AND(F14="done",H14="done"),AND(F14="done",I14="done"),AND(G14="done",H14="done"),AND(G14="done",I14="done"),AND(H14="done",I14="done")),"done 2 lession",IF(OR(F14="done",G14="done",H14="done",I14="done"),"done 1 lession","NY")))) -> done all | K14: =VLOOKUP($D14,[1]Bai1_View!$E$2:$J$177,5,FALSE) -> HCM | L14: =VLOOKUP($D14,[1]Bai1_View!$E$2:$J$177,6,FALSE) -> A. Tri | M14: =IFERROR(VLOOKUP(D14,[2]Hồng!$D$1:$M$21,10,FALSE),0) -> 0 | N14: done 1 lession | O14: 39 | W14: Cần Thơ | X14: 1
A15: 13 | B15: Nguyễn Bích Thảo | C15: Nhà thuốc Thanh Tâm | D15: 0915960698 | E15: 105/168, P.Ngọc Khánh,Ba Đình,Hà Nội | F15: =IFERROR(VLOOKUP(D15,[3]Bai1_VuotQua!$D$8:$I$143,6,FALSE),"NY") -> done | G15: =IFERROR(VLOOKUP(D15,[3]Bai2_VuotQua!$D$8:$I$120,6,FALSE),"NY") -> done | H15: =IFERROR(VLOOKUP(D15,[3]Bai3_VuotQua!$D$8:$I$122,6,FALSE),"NY") -> done | I15: =IFERROR(VLOOKUP(D15,[3]Bai4_VuotQua!$D$8:$I$117,6,FALSE),"NY") -> NY | J15: =IF(AND(F15="done",G15="done",H15="done",I15="done"),"done all",IF(OR(AND(F15="done",G15="done",H15="done"),AND(F15="done",G15="done",I15="done"),AND(F15="done",H15="done",I15="done"),AND(G15="done",H15="done",I15="done")),"done 3 lession",IF(OR(AND(F15="done",G15="done"),AND(F15="done",H15="done"),AND(F15="done",I15="done"),AND(G15="done",H15="done"),AND(G15="done",I15="done"),AND(H15="done",I15="done")),"done 2 lession",IF(OR(F15="done",G15="done",H15="done",I15="done"),"done 1 lession","NY")))) -> done 3 lession | K15: HN | L15: C. Quy | M15: =IFERROR(VLOOKUP(D15,[2]Hồng!$D$1:$M$21,10,FALSE),0) -> 0 | N15: done 2 lession | O15: 15 | W15: Đăk Lăk | X15: 3
A16: 14 | B16: trần thị thơm | C16: quầy thuốc số 11 | D16: 0978974964 | E16: quốc lộ 14, P.Pơng Drang,Krông Búk,Đắk Lắk | F16: =IFERROR(VLOOKUP(D16,[3]Bai1_VuotQua!$D$8:$I$143,6,FALSE),"NY") -> NY | G16: =IFERROR(VLOOKUP(D16,[3]Bai2_VuotQua!$D$8:$I$120,6,FALSE),"NY") -> done | H16: =IFERROR(VLOOKUP(D16,[3]Bai3_VuotQua!$D$8:$I$122,6,FALSE),"NY") -> done | I16: =IFERROR(VLOOKUP(D16,[3]Bai4_VuotQua!$D$8:$I$117,6,FALSE),"NY") -> done | J16: =IF(AND(F16="done",G16="done",H16="done",I16="done"),"done all",IF(OR(AND(F16="done",G16="done",H16="done"),AND(F16="done",G16="done",I16="done"),AND(F16="done",H16="done",I16="done"),AND(G16="done",H16="done",I16="done")),"done 3 lession",IF(OR(AND(F16="done",G16="done"),AND(F16="done",H16="done"),AND(F16="done",I16="done"),AND(G16="done",H16="done"),AND(G16="done",I16="done"),AND(H16="done",I16="done")),"done 2 lession",IF(OR(F16="done",G16="done",H16="done",I16="done"),"done 1 lession","NY")))) -> done 3 lession | K16: =VLOOKUP($D16,[1]Bai1_View!$E$2:$J$177,5,FALSE) -> Đăk Lăk | L16: =VLOOKUP($D16,[1]Bai1_View!$E$2:$J$177,6,FALSE) -> A. Tho | M16: =IFERROR(VLOOKUP(D16,[2]Hồng!$D$1:$M$21,10,FALSE),0) -> 0 | N16: done 3 lession | O16: 15 | W16: Đồng Nai | X16: 3
A17: 15 | B17: Vn-Location-3839 | C17: NT Ngọc Việt | D17: 0902117077 | E17: 198 Xã Đàn, P.Ô Chợ Dừa,Đống Đa,Hà Nội | F17: =IFERROR(VLOOKUP(D17,[3]Bai1_VuotQua!$D$8:$I$143,6,FALSE),"NY") -> done | G17: =IFERROR(VLOOKUP(D17,[3]Bai2_VuotQua!$D$8:$I$120,6,FALSE),"NY") -> done | H17: =IFERROR(VLOOKUP(D17,[3]Bai3_VuotQua!$D$8:$I$122,6,FALSE),"NY") -> done | I17: =IFERROR(VLOOKUP(D17,[3]Bai4_VuotQua!$D$8:$I$117,6,FALSE),"NY") -> done | J17: =IF(AND(F17="done",G17="done",H17="done",I17="done"),"done all",IF(OR(AND(F17="done",G17="done",H17="done"),AND(F17="done",G17="done",I17="done"),AND(F17="done",H17="done",I17="done"),AND(G17="done",H17="done",I17="done")),"done 3 lession",IF(OR(AND(F17="done",G17="done"),AND(F17="done",H17="done"),AND(F17="done",I17="done"),AND(G17="done",H17="done"),AND(G17="done",I17="done"),AND(H17="done",I17="done")),"done 2 lession",IF(OR(F17="done",G17="done",H17="done",I17="done"),"done 1 lession","NY")))) -> done all | K17: =VLOOKUP($D17,[1]Bai1_View!$E$2:$J$177,5,FALSE) -> HN | L17: =VLOOKUP($D17,[1]Bai1_View!$E$2:$J$177,6,FALSE) -> C. Quy | M17: =IFERROR(VLOOKUP(D17,[2]Hồng!$D$1:$M$21,10,FALSE),0) -> 0 | N17: done all | O17: 92 | W17: Khánh Hòa | X17: 4
A18: 16 | B18: Vũ Hồng Mỹ | C18: Nhà thuốc Long | D18: 0903325275 | E18: 12, P.Đội Cấn,Ba Đình,Hà Nội | F18: =IFERROR(VLOOKUP(D18,[3]Bai1_VuotQua!$D$8:$I$143,6,FALSE),"NY") -> done | G18: =IFERROR(VLOOKUP(D18,[3]Bai2_VuotQua!$D$8:$I$120,6,FALSE),"NY") -> done | H18: =IFERROR(VLOOKUP(D18,[3]Bai3_VuotQua!$D$8:$I$122,6,FALSE),"NY") -> done | I18: =IFERROR(VLOOKUP(D18,[3]Bai4_VuotQua!$D$8:$I$117,6,FALSE),"NY") -> done | J18: =IF(AND(F18="done",G18="done",H18="done",I18="done"),"done all",IF(OR(AND(F18="done",G18="done",H18="done"),AND(F18="done",G18="done",I18="done"),AND(F18="done",H18="done",I18="done"),AND(G18="done",H18="done",I18="done")),"done 3 lession",IF(OR(AND(F18="done",G18="done"),AND(F18="done",H18="done"),AND(F18="done",I18="done"),AND(G18="done",H18="done"),AND(G18="done",I18="done"),AND(H18="done",I18="done")),"done 2 lession",IF(OR(F18="done",G18="done",H18="done",I18="done"),"done 1 lession","NY")))) -> done all | K18: HN | L18: C. Quy | M18: =IFERROR(VLOOKUP(D18,[2]Hồng!$D$1:$M$21,10,FALSE),0) -> 0 | N18: NY | O18: 121 | V18: done 2 lession | W18: Cần Thơ | X18: 1
A19: 17 | B19: la kim ngọc | C19: NHA THUOC MINH KHANG 2 | D19: 0704968018 | E19: 110/12 NGUYEN VIET HONG- P. AN PHU, P.An Phú,Ninh Kiều,Cần Thơ | F19: =IFERROR(VLOOKUP(D19,[3]Bai1_VuotQua!$D$8:$I$143,6,FALSE),"NY") -> NY | G19: =IFERROR(VLOOKUP(D19,[3]Bai2_VuotQua!$D$8:$I$120,6,FALSE),"NY") -> done | H19: =IFERROR(VLOOKUP(D19,[3]Bai3_VuotQua!$D$8:$I$122,6,FALSE),"NY") -> done | I19: =IFERROR(VLOOKUP(D19,[3]Bai4_VuotQua!$D$8:$I$117,6,FALSE),"NY") -> done | J19: =IF(AND(F19="done",G19="done",H19="done",I19="done"),"done all",IF(OR(AND(F19="done",G19="done",H19="done"),AND(F19="done",G19="done",I19="done"),AND(F19="done",H19="done",I19="done"),AND(G19="done",H19="done",I19="done")),"done 3 lession",IF(OR(AND(F19="done",G19="done"),AND(F19="done",H19="done"),AND(F19="done",I19="done"),AND(G19="done",H19="done"),AND(G19="done",I19="done"),AND(H19="done",I19="done")),"done 2 lession",IF(OR(F19="done",G19="done",H19="done",I19="done"),"done 1 lession","NY")))) -> done 3 lession | K19: =VLOOKUP($D19,[1]Bai1_View!$E$2:$J$177,5,FALSE) -> Cần Thơ | L19: =VLOOKUP($D19,[1]Bai1_View!$E$2:$J$177,6,FALSE) -> A. Tho | M19: =IFERROR(VLOOKUP(D19,[2]Hồng!$D$1:$M$21,10,FALSE),0) -> 0 | N19: Grand Total | O19: 282 | W19: Đăk Lăk | X19: 1
A20: 18 | B20: NGUYỄN KHẮC QUỐC ĐẠT | C20: NHÀ THUỐC BẢO THI 3 | D20: 0907089624 | E20: 79D4, Khu Vực Thạnh Mỹ, P.Thường Thạnh,Cái Răng,Cần Thơ | F20: =IFERROR(VLOOKUP(D20,[3]Bai1_VuotQua!$D$8:$I$143,6,FALSE),"NY") -> done | G20: =IFERROR(VLOOKUP(D20,[3]Bai2_VuotQua!$D$8:$I$120,6,FALSE),"NY") -> done | H20: =IFERROR(VLOOKUP(D20,[3]Bai3_VuotQua!$D$8:$I$122,6,FALSE),"NY") -> done | I20: =IFERROR(VLOOKUP(D20,[3]Bai4_VuotQua!$D$8:$I$117,6,FALSE),"NY") -> done | J20: =IF(AND(F20="done",G20="done",H20="done",I20="done"),"done all",IF(OR(AND(F20="done",G20="done",H20="done"),AND(F20="done",G20="done",I20="done"),AND(F20="done",H20="done",I20="done"),AND(G20="done",H20="done",I20="done")),"done 3 lession",IF(OR(AND(F20="done",G20="done"),AND(F20="done",H20="done"),AND(F20="done",I20="done"),AND(G20="done",H20="done"),AND(G20="done",I20="done"),AND(H20="done",I20="done")),"done 2 lession",IF(OR(F20="done",G20="done",H20="done",I20="done"),"done 1 lession","NY")))) -> done all | K20: =VLOOKUP($D20,[1]Bai1_View!$E$2:$J$177,5,FALSE) -> Cần Thơ | L20: =VLOOKUP($D20,[1]Bai1_View!$E$2:$J$177,6,FALSE) -> A. Tho | M20: =IFERROR(VLOOKUP(D20,[2]Hồng!$D$1:$M$21,10,FALSE),0) -> 0 | W20: Đồng Nai | X20: 2
A21: 19 | B21: Phạm Thị Sắc | C21: nhà thuốc Lê Thị Trà Giang | D21: 0335720069 | E21: 626 minh khai, P.Vĩnh Tuy,Hai Bà Trưng,Hà Nội | F21: =IFERROR(VLOOKUP(D21,[3]Bai1_VuotQua!$D$8:$I$143,6,FALSE),"NY") -> done | G21: =IFERROR(VLOOKUP(D21,[3]Bai2_VuotQua!$D$8:$I$120,6,FALSE),"NY") -> NY | H21: =IFERROR(VLOOKUP(D21,[3]Bai3_VuotQua!$D$8:$I$122,6,FALSE),"NY") -> NY | I21: =IFERROR(VLOOKUP(D21,[3]Bai4_VuotQua!$D$8:$I$117,6,FALSE),"NY") -> NY | J21: =IF(AND(F21="done",G21="done",H21="done",I21="done"),"done all",IF(OR(AND(F21="done",G21="done",H21="done"),AND(F21="done",G21="done",I21="done"),AND(F21="done",H21="done",I21="done"),AND(G21="done",H21="done",I21="done")),"done 3 lession",IF(OR(AND(F21="done",G21="done"),AND(F21="done",H21="done"),AND(F21="done",I21="done"),AND(G21="done",H21="done"),AND(G21="done",I21="done"),AND(H21="done",I21="done")),"done 2 lession",IF(OR(F21="done",G21="done",H21="done",I21="done"),"done 1 lession","NY")))) -> done 1 lession | K21: =VLOOKUP($D21,[1]Bai1_View!$E$2:$J$177,5,FALSE) -> HN | L21: =VLOOKUP($D21,[1]Bai1_View!$E$2:$J$177,6,FALSE) -> C. Quy | M21: =IFERROR(VLOOKUP(D21,[2]Hồng!$D$1:$M$21,10,FALSE),0) -> 0 | W21: Đồng Tháp | X21: 1
A22: 20 | B22: Nguyễn thị mỹ phúc | C22: Nhà thuốc Trường Phúc | D22: 0934567663 | E22: Trần Hưng Đạo, P.Mỹ Thới,Long Xuyên,An Giang | F22: =IFERROR(VLOOKUP(D22,[3]Bai1_VuotQua!$D$8:$I$143,6,FALSE),"NY") -> NY | G22: =IFERROR(VLOOKUP(D22,[3]Bai2_VuotQua!$D$8:$I$120,6,FALSE),"NY") -> NY | H22: =IFERROR(VLOOKUP(D22,[3]Bai3_VuotQua!$D$8:$I$122,6,FALSE),"NY") -> NY | I22: =IFERROR(VLOOKUP(D22,[3]Bai4_VuotQua!$D$8:$I$117,6,FALSE),"NY") -> NY | J22: =IF(AND(F22="done",G22="done",H22="done",I22="done"),"done all",IF(OR(AND(F22="done",G22="done",H22="done"),AND(F22="done",G22="done",I22="done"),AND(F22="done",H22="done",I22="done"),AND(G22="done",H22="done",I22="done")),"done 3 lession",IF(OR(AND(F22="done",G22="done"),AND(F22="done",H22="done"),AND(F22="done",I22="done"),AND(G22="done",H22="done"),AND(G22="done",I22="done"),AND(H22="done",I22="done")),"done 2 lession",IF(OR(F22="done",G22="done",H22="done",I22="done"),"done 1 lession","NY")))) -> NY | K22: =VLOOKUP($D22,[1]Bai1_View!$E$2:$J$177,5,FALSE) -> An Giang | L22: =VLOOKUP($D22,[1]Bai1_View!$E$2:$J$177,6,FALSE) -> A. Tho | M22: =IFERROR(VLOOKUP(D22,[2]Hồng!$D$1:$M$21,10,FALSE),0) -> 0 | V22: done 3 lession | W22: Cần Thơ | X22: 1
A23: 21 | B23: Loan | C23: test | D23: 0766855066 | E23: 178, P.Tân An,Ninh Kiều,Cần Thơ | F23: =IFERROR(VLOOKUP(D23,[3]Bai1_VuotQua!$D$8:$I$143,6,FALSE),"NY") -> done | G23: =IFERROR(VLOOKUP(D23,[3]Bai2_VuotQua!$D$8:$I$120,6,FALSE),"NY") -> done | H23: =IFERROR(VLOOKUP(D23,[3]Bai3_VuotQua!$D$8:$I$122,6,FALSE),"NY") -> done | I23: =IFERROR(VLOOKUP(D23,[3]Bai4_VuotQua!$D$8:$I$117,6,FALSE),"NY") -> done | J23: =IF(AND(F23="done",G23="done",H23="done",I23="done"),"done all",IF(OR(AND(F23="done",G23="done",H23="done"),AND(F23="done",G23="done",I23="done"),AND(F23="done",H23="done",I23="done"),AND(G23="done",H23="done",I23="done")),"done 3 lession",IF(OR(AND(F23="done",G23="done"),AND(F23="done",H23="done"),AND(F23="done",I23="done"),AND(G23="done",H23="done"),AND(G23="done",I23="done"),AND(H23="done",I23="done")),"done 2 lession",IF(OR(F23="done",G23="done",H23="done",I23="done"),"done 1 lession","NY")))) -> done all | K23: =VLOOKUP($D23,[1]Bai1_View!$E$2:$J$177,5,FALSE) -> Cần Thơ | L23: =VLOOKUP($D23,[1]Bai1_View!$E$2:$J$177,6,FALSE) -> A. Tho | M23: =IFERROR(VLOOKUP(D23,[2]Hồng!$D$1:$M$21,10,FALSE),0) -> 0 | W23: Đăk Lăk | X23: 1
A24: 22 | B24: Nguyễn Thế Dương | C24: Nhà Thuốc Diễm Nhi | D24: 0904983201 | E24: 23 Hồ Bá Kiện,, P.15,Quận 10,Hồ Chí Minh | F24: =IFERROR(VLOOKUP(D24,[3]Bai1_VuotQua!$D$8:$I$143,6,FALSE),"NY") -> NY | G24: =IFERROR(VLOOKUP(D24,[3]Bai2_VuotQua!$D$8:$I$120,6,FALSE),"NY") -> NY | H24: =IFERROR(VLOOKUP(D24,[3]Bai3_VuotQua!$D$8:$I$122,6,FALSE),"NY") -> NY | I24: =IFERROR(VLOOKUP(D24,[3]Bai4_VuotQua!$D$8:$I$117,6,FALSE),"NY") -> NY | J24: =IF(AND(F24="done",G24="done",H24="done",I24="done"),"done all",IF(OR(AND(F24="done",G24="done",H24="done"),AND(F24="done",G24="done",I24="done"),AND(F24="done",H24="done",I24="done"),AND(G24="done",H24="done",I24="done")),"done 3 lession",IF(OR(AND(F24="done",G24="done"),AND(F24="done",H24="done"),AND(F24="done",I24="done"),AND(G24="done",H24="done"),AND(G24="done",I24="done"),AND(H24="done",I24="done")),"done 2 lession",IF(OR(F24="done",G24="done",H24="done",I24="done"),"done 1 lession","NY")))) -> NY | K24: HCM | L24: A. Tri | M24: =IFERROR(VLOOKUP(D24,[2]Hồng!$D$1:$M$21,10,FALSE),0) -> 0 | W24: Đồng Nai | X24: 4
A25: 23 | B25: Phạm Thị Mơ | C25: nhà thuốc Anh Tuấn | D25: 0986190286 | E25: 204 hồng mai, P.Quỳnh Lôi,Hai Bà Trưng,Hà Nội | F25: =IFERROR(VLOOKUP(D25,[3]Bai1_VuotQua!$D$8:$I$143,6,FALSE),"NY") -> done | G25: =IFERROR(VLOOKUP(D25,[3]Bai2_VuotQua!$D$8:$I$120,6,FALSE),"NY") -> done | H25: =IFERROR(VLOOKUP(D25,[3]Bai3_VuotQua!$D$8:$I$122,6,FALSE),"NY") -> done | I25: =IFERROR(VLOOKUP(D25,[3]Bai4_VuotQua!$D$8:$I$117,6,FALSE),"NY") -> done | J25: =IF(AND(F25="done",G25="done",H25="done",I25="done"),"done all",IF(OR(AND(F25="done",G25="done",H25="done"),AND(F25="done",G25="done",I25="done"),AND(F25="done",H25="done",I25="done"),AND(G25="done",H25="done",I25="done")),"done 3 lession",IF(OR(AND(F25="done",G25="done"),AND(F25="done",H25="done"),AND(F25="done",I25="done"),AND(G25="done",H25="done"),AND(G25="done",I25="done"),AND(H25="done",I25="done")),"done 2 lession",IF(OR(F25="done",G25="done",H25="done",I25="done"),"done 1 lession","NY")))) -> done all | K25: HN | L25: C. Quy | M25: =IFERROR(VLOOKUP(D25,[2]Hồng!$D$1:$M$21,10,FALSE),0) -> ok | V25: done all | W25: Cần Thơ | X25: 15
A26: 24 | B26: C Hằng | C26: NT Thanh Binh | D26: 0374635903 | E26: 14 Trần Nhân Tông, P.Nguyễn Du,Hai Bà Trưng,Hà Nội | F26: =IFERROR(VLOOKUP(D26,[3]Bai1_VuotQua!$D$8:$I$143,6,FALSE),"NY") -> done | G26: =IFERROR(VLOOKUP(D26,[3]Bai2_VuotQua!$D$8:$I$120,6,FALSE),"NY") -> done | H26: =IFERROR(VLOOKUP(D26,[3]Bai3_VuotQua!$D$8:$I$122,6,FALSE),"NY") -> done | I26: =IFERROR(VLOOKUP(D26,[3]Bai4_VuotQua!$D$8:$I$117,6,FALSE),"NY") -> done | J26: =IF(AND(F26="done",G26="done",H26="done",I26="done"),"done all",IF(OR(AND(F26="done",G26="done",H26="done"),AND(F26="done",G26="done",I26="done"),AND(F26="done",H26="done",I26="done"),AND(G26="done",H26="done",I26="done")),"done 3 lession",IF(OR(AND(F26="done",G26="done"),AND(F26="done",H26="done"),AND(F26="done",I26="done"),AND(G26="done",H26="done"),AND(G26="done",I26="done"),AND(H26="done",I26="done")),"done 2 lession",IF(OR(F26="done",G26="done",H26="done",I26="done"),"done 1 lession","NY")))) -> done all | K26: HN | L26: C. Quy | M26: =IFERROR(VLOOKUP(D26,[2]Hồng!$D$1:$M$21,10,FALSE),0) -> ok | W26: Đăk Lăk | X26: 4
A27: 25 | B27: Nguyễn Hạnh | C27: Nhà thuốc huy hoàng | D27: 09455882666 | E27: 38 nguyễn Thiệp, P.Đồng Xuân,Hoàn Kiếm,Hà Nội | F27: =IFERROR(VLOOKUP(D27,[3]Bai1_VuotQua!$D$8:$I$143,6,FALSE),"NY") -> NY | G27: =IFERROR(VLOOKUP(D27,[3]Bai2_VuotQua!$D$8:$I$120,6,FALSE),"NY") -> NY | H27: =IFERROR(VLOOKUP(D27,[3]Bai3_VuotQua!$D$8:$I$122,6,FALSE),"NY") -> NY | I27: =IFERROR(VLOOKUP(D27,[3]Bai4_VuotQua!$D$8:$I$117,6,FALSE),"NY") -> NY | J27: =IF(AND(F27="done",G27="done",H27="done",I27="done"),"done all",IF(OR(AND(F27="done",G27="done",H27="done"),AND(F27="done",G27="done",I27="done"),AND(F27="done",H27="done",I27="done"),AND(G27="done",H27="done",I27="done")),"done 3 lession",IF(OR(AND(F27="done",G27="done"),AND(F27="done",H27="done"),AND(F27="done",I27="done"),AND(G27="done",H27="done"),AND(G27="done",I27="done"),AND(H27="done",I27="done")),"done 2 lession",IF(OR(F27="done",G27="done",H27="done",I27="done"),"done 1 lession","NY")))) -> NY | K27: HN | L27: C. Quy | M27: =IFERROR(VLOOKUP(D27,[2]Hồng!$D$1:$M$21,10,FALSE),0) -> 0 | W27: Đồng Nai | X27: 12
A28: 26 | B28: chinh | C28: chinh ánh | D28: 0385750840 | E28: 45, P.Nghĩa Đô,Cầu Giấy,Hà Nội | F28: =IFERROR(VLOOKUP(D28,[3]Bai1_VuotQua!$D$8:$I$143,6,FALSE),"NY") -> NY | G28: =IFERROR(VLOOKUP(D28,[3]Bai2_VuotQua!$D$8:$I$120,6,FALSE),"NY") -> NY | H28: =IFERROR(VLOOKUP(D28,[3]Bai3_VuotQua!$D$8:$I$122,6,FALSE),"NY") -> NY | I28: =IFERROR(VLOOKUP(D28,[3]Bai4_VuotQua!$D$8:$I$117,6,FALSE),"NY") -> NY | J28: =IF(AND(F28="done",G28="done",H28="done",I28="done"),"done all",IF(OR(AND(F28="done",G28="done",H28="done"),AND(F28="done",G28="done",I28="done"),AND(F28="done",H28="done",I28="done"),AND(G28="done",H28="done",I28="done")),"done 3 lession",IF(OR(AND(F28="done",G28="done"),AND(F28="done",H28="done"),AND(F28="done",I28="done"),AND(G28="done",H28="done"),AND(G28="done",I28="done"),AND(H28="done",I28="done")),"done 2 lession",IF(OR(F28="done",G28="done",H28="done",I28="done"),"done 1 lession","NY")))) -> NY | K28: =VLOOKUP($D28,[1]Bai1_View!$E$2:$J$177,5,FALSE) -> HN | L28: =VLOOKUP($D28,[1]Bai1_View!$E$2:$J$177,6,FALSE) -> C. Quy | M28: =IFERROR(VLOOKUP(D28,[2]Hồng!$D$1:$M$21,10,FALSE),0) -> 0 | W28: Khánh Hòa | X28: 4
A29: 27 | B29: Ngô Thi Lâm Thuân | C29: NT BAO KHOI | D29: 0908412436 | E29: 702 HUONG LO 2, P. BINH TRI DONG A, P.Bình Hưng Hòa,Bình Tân,Hồ Chí Minh | F29: =IFERROR(VLOOKUP(D29,[3]Bai1_VuotQua!$D$8:$I$143,6,FALSE),"NY") -> done | G29: =IFERROR(VLOOKUP(D29,[3]Bai2_VuotQua!$D$8:$I$120,6,FALSE),"NY") -> done | H29: =IFERROR(VLOOKUP(D29,[3]Bai3_VuotQua!$D$8:$I$122,6,FALSE),"NY") -> done | I29: =IFERROR(VLOOKUP(D29,[3]Bai4_VuotQua!$D$8:$I$117,6,FALSE),"NY") -> done | J29: =IF(AND(F29="done",G29="done",H29="done",I29="done"),"done all",IF(OR(AND(F29="done",G29="done",H29="done"),AND(F29="done",G29="done",I29="done"),AND(F29="done",H29="done",I29="done"),AND(G29="done",H29="done",I29="done")),"done 3 lession",IF(OR(AND(F29="done",G29="done"),AND(F29="done",H29="done"),AND(F29="done",I29="done"),AND(G29="done",H29="done"),AND(G29="done",I29="done"),AND(H29="done",I29="done")),"done 2 lession",IF(OR(F29="done",G29="done",H29="done",I29="done"),"done 1 lession","NY")))) -> done all | K29: =VLOOKUP($D29,[1]Bai1_View!$E$2:$J$177,5,FALSE) -> HCM | L29: =VLOOKUP($D29,[1]Bai1_View!$E$2:$J$177,6,FALSE) -> A. Tri | M29: =IFERROR(VLOOKUP(D29,[2]Hồng!$D$1:$M$21,10,FALSE),0) -> 0 | V29: NY | W29: An Giang | X29: 5
A30: 28 | B30: Le thi kim chi | C30: NT Hoa Mai | D30: 0902485557 | E30: 011 Chung Cư Tân Sơn Nhì, P.14,Tân Bình,Hồ Chí Minh | F30: =IFERROR(VLOOKUP(D30,[3]Bai1_VuotQua!$D$8:$I$143,6,FALSE),"NY") -> done | G30: =IFERROR(VLOOKUP(D30,[3]Bai2_VuotQua!$D$8:$I$120,6,FALSE),"NY") -> NY | H30: =IFERROR(VLOOKUP(D30,[3]Bai3_VuotQua!$D$8:$I$122,6,FALSE),"NY") -> NY | I30: =IFERROR(VLOOKUP(D30,[3]Bai4_VuotQua!$D$8:$I$117,6,FALSE),"NY") -> NY | J30: =IF(AND(F30="done",G30="done",H30="done",I30="done"),"done all",IF(OR(AND(F30="done",G30="done",H30="done"),AND(F30="done",G30="done",I30="done"),AND(F30="done",H30="done",I30="done"),AND(G30="done",H30="done",I30="done")),"done 3 lession",IF(OR(AND(F30="done",G30="done"),AND(F30="done",H30="done"),AND(F30="done",I30="done"),AND(G30="done",H30="done"),AND(G30="done",I30="done"),AND(H30="done",I30="done")),"done 2 lession",IF(OR(F30="done",G30="done",H30="done",I30="done"),"done 1 lession","NY")))) -> done 1 lession | K30: =VLOOKUP($D30,[1]Bai1_View!$E$2:$J$177,5,FALSE) -> HCM | L30: =VLOOKUP($D30,[1]Bai1_View!$E$2:$J$177,6,FALSE) -> A. Tri | M30: =IFERROR(VLOOKUP(D30,[2]Hồng!$D$1:$M$21,10,FALSE),0) -> 0 | W30: Bình Dương | X30: 1
A31: 29 | B31: Nguyễn Thanh Xuân Nữ | C31: Quầy Thuốc Mỹ Anh | D31: 0913143031 | E31: 197, đường 1/5,, P.Tràm Chim,Tam Nông,Đồng Tháp | F31: =IFERROR(VLOOKUP(D31,[3]Bai1_VuotQua!$D$8:$I$143,6,FALSE),"NY") -> done | G31: =IFERROR(VLOOKUP(D31,[3]Bai2_VuotQua!$D$8:$I$120,6,FALSE),"NY") -> NY | H31: =IFERROR(VLOOKUP(D31,[3]Bai3_VuotQua!$D$8:$I$122,6,FALSE),"NY") -> NY | I31: =IFERROR(VLOOKUP(D31,[3]Bai4_VuotQua!$D$8:$I$117,6,FALSE),"NY") -> done | J31: =IF(AND(F31="done",G31="done",H31="done",I31="done"),"done all",IF(OR(AND(F31="done",G31="done",H31="done"),AND(F31="done",G31="done",I31="done"),AND(F31="done",H31="done",I31="done"),AND(G31="done",H31="done",I31="done")),"done 3 lession",IF(OR(AND(F31="done",G31="done"),AND(F31="done",H31="done"),AND(F31="done",I31="done"),AND(G31="done",H31="done"),AND(G31="done",I31="done"),AND(H31="done",I31="done")),"done 2 lession",IF(OR(F31="done",G31="done",H31="done",I31="done"),"done 1 lession","NY")))) -> done 2 lession | K31: =VLOOKUP($D31,[1]Bai1_View!$E$2:$J$177,5,FALSE) -> Đồng Tháp | L31: =VLOOKUP($D31,[1]Bai1_View!$E$2:$J$177,6,FALSE) -> A. Tho | M31: =IFERROR(VLOOKUP(D31,[2]Hồng!$D$1:$M$21,10,FALSE),0) -> 0 | W31: Cần Thơ | X31: 4
A32: 30 | B32: Ngô thị Yến | C32: nhà thuốc Nguyễn thị kim liên | D32: 0398019788 | E32: Số 72 phố Trần Bình, P.Mai Dịch,Cầu Giấy,Hà Nội | F32: =IFERROR(VLOOKUP(D32,[3]Bai1_VuotQua!$D$8:$I$143,6,FALSE),"NY") -> done | G32: =IFERROR(VLOOKUP(D32,[3]Bai2_VuotQua!$D$8:$I$120,6,FALSE),"NY") -> done | H32: =IFERROR(VLOOKUP(D32,[3]Bai3_VuotQua!$D$8:$I$122,6,FALSE),"NY") -> done | I32: =IFERROR(VLOOKUP(D32,[3]Bai4_VuotQua!$D$8:$I$117,6,FALSE),"NY") -> done | J32: =IF(AND(F32="done",G32="done",H32="done",I32="done"),"done all",IF(OR(AND(F32="done",G32="done",H32="done"),AND(F32="done",G32="done",I32="done"),AND(F32="done",H32="done",I32="done"),AND(G32="done",H32="done",I32="done")),"done 3 lession",IF(OR(AND(F32="done",G32="done"),AND(F32="done",H32="done"),AND(F32="done",I32="done"),AND(G32="done",H32="done"),AND(G32="done",I32="done"),AND(H32="done",I32="done")),"done 2 lession",IF(OR(F32="done",G32="done",H32="done",I32="done"),"done 1 lession","NY")))) -> done all | K32: HN | L32: C. Quy | M32: =IFERROR(VLOOKUP(D32,[2]Hồng!$D$1:$M$21,10,FALSE),0) -> 0 | W32: Đăk Lăk | X32: 7
A33: 31 | B33: Trần Thị Thuỳ Dương | C33: NHA THUOC BONG SAO | D33: 0932985905 | E33: 10 trần việt châu, P.An Hòa,Ninh Kiều,Cần Thơ | F33: =IFERROR(VLOOKUP(D33,[3]Bai1_VuotQua!$D$8:$I$143,6,FALSE),"NY") -> done | G33: =IFERROR(VLOOKUP(D33,[3]Bai2_VuotQua!$D$8:$I$120,6,FALSE),"NY") -> NY | H33: =IFERROR(VLOOKUP(D33,[3]Bai3_VuotQua!$D$8:$I$122,6,FALSE),"NY") -> NY | I33: =IFERROR(VLOOKUP(D33,[3]Bai4_VuotQua!$D$8:$I$117,6,FALSE),"NY") -> NY | J33: =IF(AND(F33="done",G33="done",H33="done",I33="done"),"done all",IF(OR(AND(F33="done",G33="done",H33="done"),AND(F33="done",G33="done",I33="done"),AND(F33="done",H33="done",I33="done"),AND(G33="done",H33="done",I33="done")),"done 3 lession",IF(OR(AND(F33="done",G33="done"),AND(F33="done",H33="done"),AND(F33="done",I33="done"),AND(G33="done",H33="done"),AND(G33="done",I33="done"),AND(H33="done",I33="done")),"done 2 lession",IF(OR(F33="done",G33="done",H33="done",I33="done"),"done 1 lession","NY")))) -> done 1 lession | K33: =VLOOKUP($D33,[1]Bai1_View!$E$2:$J$177,5,FALSE) -> Cần Thơ | L33: =VLOOKUP($D33,[1]Bai1_View!$E$2:$J$177,6,FALSE) -> A. Tho | M33: =IFERROR(VLOOKUP(D33,[2]Hồng!$D$1:$M$21,10,FALSE),0) -> 0 | W33: Đồng Tháp | X33: 1
A34: 32 | B34: Âu Chí Kiên | C34: Nhà Thuốc Phương Thảo | D34: 0938980689 | E34: 08 lô C Mạc Thiên Tích , P.11,Quận 5,Hồ Chí Minh | F34: =IFERROR(VLOOKUP(D34,[3]Bai1_VuotQua!$D$8:$I$143,6,FALSE),"NY") -> done | G34: =IFERROR(VLOOKUP(D34,[3]Bai2_VuotQua!$D$8:$I$120,6,FALSE),"NY") -> done | H34: =IFERROR(VLOOKUP(D34,[3]Bai3_VuotQua!$D$8:$I$122,6,FALSE),"NY") -> done | I34: =IFERROR(VLOOKUP(D34,[3]Bai4_VuotQua!$D$8:$I$117,6,FALSE),"NY") -> done | J34: =IF(AND(F34="done",G34="done",H34="done",I34="done"),"done all",IF(OR(AND(F34="done",G34="done",H34="done"),AND(F34="done",G34="done",I34="done"),AND(F34="done",H34="done",I34="done"),AND(G34="done",H34="done",I34="done")),"done 3 lession",IF(OR(AND(F34="done",G34="done"),AND(F34="done",H34="done"),AND(F34="done",I34="done"),AND(G34="done",H34="done"),AND(G34="done",I34="done"),AND(H34="done",I34="done")),"done 2 lession",IF(OR(F34="done",G34="done",H34="done",I34="done"),"done 1 lession","NY")))) -> done all | K34: =VLOOKUP($D34,[1]Bai1_View!$E$2:$J$177,5,FALSE) -> HCM | L34: =VLOOKUP($D34,[1]Bai1_View!$E$2:$J$177,6,FALSE) -> A. Tri | M34: =IFERROR(VLOOKUP(D34,[2]Hồng!$D$1:$M$21,10,FALSE),0) -> 0 | W34: Khánh Hòa | X34: 6
A35: 33 | B35: Thái thị huệ | C35: nhà thuốc DS Vu Van Thu | D35: 0982600388 | E35: 81B xuân diệu, P.Quảng An,Tây Hồ,Hà Nội | F35: =IFERROR(VLOOKUP(D35,[3]Bai1_VuotQua!$D$8:$I$143,6,FALSE),"NY") -> done | G35: =IFERROR(VLOOKUP(D35,[3]Bai2_VuotQua!$D$8:$I$120,6,FALSE),"NY") -> done | H35: =IFERROR(VLOOKUP(D35,[3]Bai3_VuotQua!$D$8:$I$122,6,FALSE),"NY") -> done | I35: =IFERROR(VLOOKUP(D35,[3]Bai4_VuotQua!$D$8:$I$117,6,FALSE),"NY") -> done | J35: =IF(AND(F35="done",G35="done",H35="done",I35="done"),"done all",IF(OR(AND(F35="done",G35="done",H35="done"),AND(F35="done",G35="done",I35="done"),AND(F35="done",H35="done",I35="done"),AND(G35="done",H35="done",I35="done")),"done 3 lession",IF(OR(AND(F35="done",G35="done"),AND(F35="done",H35="done"),AND(F35="done",I35="done"),AND(G35="done",H35="done"),AND(G35="done",I35="done"),AND(H35="done",I35="done")),"done 2 lession",IF(OR(F35="done",G35="done",H35="done",I35="done"),"done 1 lession","NY")))) -> done all | K35: =VLOOKUP($D35,[1]Bai1_View!$E$2:$J$177,5,FALSE) -> HN | L35: =VLOOKUP($D35,[1]Bai1_View!$E$2:$J$177,6,FALSE) -> C. Quy | M35: =IFERROR(VLOOKUP(D35,[2]Hồng!$D$1:$M$21,10,FALSE),0) -> 0 | U35: A. Tho Total | X35: 84
A36: 34 | B36: Đỗ ngọc anh | C36: nhà thuốc số 27 | D36: 0981682196 | E36: 192 dãy 1 sa la, P.Phú La,Hà Đông,Hà Nội | F36: =IFERROR(VLOOKUP(D36,[3]Bai1_VuotQua!$D$8:$I$143,6,FALSE),"NY") -> NY | G36: =IFERROR(VLOOKUP(D36,[3]Bai2_VuotQua!$D$8:$I$120,6,FALSE),"NY") -> NY | H36: =IFERROR(VLOOKUP(D36,[3]Bai3_VuotQua!$D$8:$I$122,6,FALSE),"NY") -> NY | I36: =IFERROR(VLOOKUP(D36,[3]Bai4_VuotQua!$D$8:$I$117,6,FALSE),"NY") -> NY | J36: =IF(AND(F36="done",G36="done",H36="done",I36="done"),"done all",IF(OR(AND(F36="done",G36="done",H36="done"),AND(F36="done",G36="done",I36="done"),AND(F36="done",H36="done",I36="done"),AND(G36="done",H36="done",I36="done")),"done 3 lession",IF(OR(AND(F36="done",G36="done"),AND(F36="done",H36="done"),AND(F36="done",I36="done"),AND(G36="done",H36="done"),AND(G36="done",I36="done"),AND(H36="done",I36="done")),"done 2 lession",IF(OR(F36="done",G36="done",H36="done",I36="done"),"done 1 lession","NY")))) -> NY | K36: HN | L36: C. Quy | M36: =IFERROR(VLOOKUP(D36,[2]Hồng!$D$1:$M$21,10,FALSE),0) -> 0 | U36: A. Tri | V36: done 1 lession | W36: HCM | X36: 9
A37: 35 | B37: Đỗ Thuỳ Dương | C37: Nhà thuốc Nguyên Khang | D37: 0372046246 | E37: Số nhà 168 Phùng Hưng- Hà Đông - Hà Nội, P.Phúc La,Hà Đông,Hà Nội | F37: =IFERROR(VLOOKUP(D37,[3]Bai1_VuotQua!$D$8:$I$143,6,FALSE),"NY") -> done | G37: =IFERROR(VLOOKUP(D37,[3]Bai2_VuotQua!$D$8:$I$120,6,FALSE),"NY") -> done | H37: =IFERROR(VLOOKUP(D37,[3]Bai3_VuotQua!$D$8:$I$122,6,FALSE),"NY") -> done | I37: =IFERROR(VLOOKUP(D37,[3]Bai4_VuotQua!$D$8:$I$117,6,FALSE),"NY") -> done | J37: =IF(AND(F37="done",G37="done",H37="done",I37="done"),"done all",IF(OR(AND(F37="done",G37="done",H37="done"),AND(F37="done",G37="done",I37="done"),AND(F37="done",H37="done",I37="done"),AND(G37="done",H37="done",I37="done")),"done 3 lession",IF(OR(AND(F37="done",G37="done"),AND(F37="done",H37="done"),AND(F37="done",I37="done"),AND(G37="done",H37="done"),AND(G37="done",I37="done"),AND(H37="done",I37="done")),"done 2 lession",IF(OR(F37="done",G37="done",H37="done",I37="done"),"done 1 lession","NY")))) -> done all | K37: HN | L37: C. Quy | M37: =IFERROR(VLOOKUP(D37,[2]Hồng!$D$1:$M$21,10,FALSE),0) -> 0 | V37: done 2 lession | W37: HCM | X37: 4
A38: 36 | B38: Lê Thị Tâm Uyên | C38: NT Phương Khánh | D38: 0908275696 | E38: Hai Bà Trưng, P. Mỹ Long, Tp. Long Xuyên, P.Mỹ Long,Long Xuyên,An Giang | F38: =IFERROR(VLOOKUP(D38,[3]Bai1_VuotQua!$D$8:$I$143,6,FALSE),"NY") -> done | G38: =IFERROR(VLOOKUP(D38,[3]Bai2_VuotQua!$D$8:$I$120,6,FALSE),"NY") -> NY | H38: =IFERROR(VLOOKUP(D38,[3]Bai3_VuotQua!$D$8:$I$122,6,FALSE),"NY") -> NY | I38: =IFERROR(VLOOKUP(D38,[3]Bai4_VuotQua!$D$8:$I$117,6,FALSE),"NY") -> NY | J38: =IF(AND(F38="done",G38="done",H38="done",I38="done"),"done all",IF(OR(AND(F38="done",G38="done",H38="done"),AND(F38="done",G38="done",I38="done"),AND(F38="done",H38="done",I38="done"),AND(G38="done",H38="done",I38="done")),"done 3 lession",IF(OR(AND(F38="done",G38="done"),AND(F38="done",H38="done"),AND(F38="done",I38="done"),AND(G38="done",H38="done"),AND(G38="done",I38="done"),AND(H38="done",I38="done")),"done 2 lession",IF(OR(F38="done",G38="done",H38="done",I38="done"),"done 1 lession","NY")))) -> done 1 lession | K38: =VLOOKUP($D38,[1]Bai1_View!$E$2:$J$177,5,FALSE) -> An Giang | L38: =VLOOKUP($D38,[1]Bai1_View!$E$2:$J$177,6,FALSE) -> A. Tho | M38: =IFERROR(VLOOKUP(D38,[2]Hồng!$D$1:$M$21,10,FALSE),0) -> 0 | V38: done 3 lession | W38: HCM | X38: 4
A39: 37 | B39: Trương Thị Hồng | C39: NT Hải Minh | D39: 0917266219 | E39: 47 Cửu Long, P.15,Quận 10,Hồ Chí Minh | F39: =IFERROR(VLOOKUP(D39,[3]Bai1_VuotQua!$D$8:$I$143,6,FALSE),"NY") -> done | G39: =IFERROR(VLOOKUP(D39,[3]Bai2_VuotQua!$D$8:$I$120,6,FALSE),"NY") -> done | H39: =IFERROR(VLOOKUP(D39,[3]Bai3_VuotQua!$D$8:$I$122,6,FALSE),"NY") -> done | I39: =IFERROR(VLOOKUP(D39,[3]Bai4_VuotQua!$D$8:$I$117,6,FALSE),"NY") -> done | J39: =IF(AND(F39="done",G39="done",H39="done",I39="done"),"done all",IF(OR(AND(F39="done",G39="done",H39="done"),AND(F39="done",G39="done",I39="done"),AND(F39="done",H39="done",I39="done"),AND(G39="done",H39="done",I39="done")),"done 3 lession",IF(OR(AND(F39="done",G39="done"),AND(F39="done",H39="done"),AND(F39="done",I39="done"),AND(G39="done",H39="done"),AND(G39="done",I39="done"),AND(H39="done",I39="done")),"done 2 lession",IF(OR(F39="done",G39="done",H39="done",I39="done"),"done 1 lession","NY")))) -> done all | K39: =VLOOKUP($D39,[1]Bai1_View!$E$2:$J$177,5,FALSE) -> HCM | L39: =VLOOKUP($D39,[1]Bai1_View!$E$2:$J$177,6,FALSE) -> A. Tri | M39: =IFERROR(VLOOKUP(D39,[2]Hồng!$D$1:$M$21,10,FALSE),0) -> 0 | V39: done all | W39: HCM | X39: 17
A40: 38 | B40: tran thi na | C40: nt so 86 | D40: 0979336497 | E40: 86 no trang long, P.Tân Tiến,Buôn Ma Thuột,Đắk Lắk | F40: =IFERROR(VLOOKUP(D40,[3]Bai1_VuotQua!$D$8:$I$143,6,FALSE),"NY") -> done | G40: =IFERROR(VLOOKUP(D40,[3]Bai2_VuotQua!$D$8:$I$120,6,FALSE),"NY") -> NY | H40: =IFERROR(VLOOKUP(D40,[3]Bai3_VuotQua!$D$8:$I$122,6,FALSE),"NY") -> NY | I40: =IFERROR(VLOOKUP(D40,[3]Bai4_VuotQua!$D$8:$I$117,6,FALSE),"NY") -> NY | J40: =IF(AND(F40="done",G40="done",H40="done",I40="done"),"done all",IF(OR(AND(F40="done",G40="done",H40="done"),AND(F40="done",G40="done",I40="done"),AND(F40="done",H40="done",I40="done"),AND(G40="done",H40="done",I40="done")),"done 3 lession",IF(OR(AND(F40="done",G40="done"),AND(F40="done",H40="done"),AND(F40="done",I40="done"),AND(G40="done",H40="done"),AND(G40="done",I40="done"),AND(H40="done",I40="done")),"done 2 lession",IF(OR(F40="done",G40="done",H40="done",I40="done"),"done 1 lession","NY")))) -> done 1 lession | K40: =VLOOKUP($D40,[1]Bai1_View!$E$2:$J$177,5,FALSE) -> Đăk Lăk | L40: =VLOOKUP($D40,[1]Bai1_View!$E$2:$J$177,6,FALSE) -> A. Tho | M40: =IFERROR(VLOOKUP(D40,[2]Hồng!$D$1:$M$21,10,FALSE),0) -> 0 | V40: NY | W40: HCM | X40: 45
...

Sheet Sheet2
A3: Kết quả | B3: ASM
B4: A Tuấn | C4: A Thọ | D4: A Trí | E4: C. Quý | F4: Tổng số
A5: Hoàn thành 1 bài | B5: 1 | C5: 14 | D5: 7 | E5: 14 | F5: 36
A6: Hoàn thành 2 bài | B6: 1 | C6: 6 | D6: 4 | E6: 12 | F6: 23
A7: Hoàn thành 3 bài | C7: 3 | D7: 3 | E7: 7 | F7: 13
A8: Hoàn thành tất cả | C8: 34 | D8: 12 | E8: 27 | F8: 73
A9: Không hoàn thành | B9: 9 | C9: 26 | D9: 47 | E9: 44 | F9: 126
A10: Tổng số | B10: 11 | C10: 83 | D10: 73 | E10: 104 | F10: 271

Sheet Danh sach hoàn thành
A1: STT | B1: Họ và Tên | C1: Tên nhà thuốc | D1: Số điện thoại | E1: Địa chỉ | F1: Bài 1 | G1: Bài 2 | H1: Bài 3 | I1: Bài 4 | J1: Results | K1: Khu vuc | L1: ASM
A2: 1 | B2: Phan thị Huệ | C2: nhà thuốc Đức cường | D2: 0362225885 | E2: 35 cũ nay 251 Trần Đại Nghĩa, P.Đồng Tâm,Hai Bà Trưng,Hà Nội | F2: done | G2: done | H2: done | I2: done | J2: done all | K2: HN | L2: C. Quy
A3: 2 | B3: Lê Thu Hà | C3: NT Ngân Hà | D3: 0937234829 | E3: Cong quynh, P.Phạm Ngũ Lão,Quận 1,Hồ Chí Minh | F3: done | G3: done | H3: done | I3: done | J3: done all | K3: HCM | L3: A. Tri
A4: 3 | B4: Vn-Location-3839 | C4: NT Ngọc Việt | D4: 0902117077 | E4: 198 Xã Đàn, P.Ô Chợ Dừa,Đống Đa,Hà Nội | F4: done | G4: done | H4: done | I4: done | J4: done all | K4: HN | L4: C. Quy
A5: 4 | B5: Vũ Hồng Mỹ | C5: Nhà thuốc Long | D5: 0903325275 | E5: 12, P.Đội Cấn,Ba Đình,Hà Nội | F5: done | G5: done | H5: done | I5: done | J5: done all | K5: HN | L5: C. Quy
A6: 5 | B6: NGUYỄN KHẮC QUỐC ĐẠT | C6: NHÀ THUỐC BẢO THI 3 | D6: 0907089624 | E6: 79D4, Khu Vực Thạnh Mỹ, P.Thường Thạnh,Cái Răng,Cần Thơ | F6: done | G6: done | H6: done | I6: done | J6: done all | K6: Cần Thơ | L6: A. Tho
A7: 6 | B7: Loan | C7: test | D7: 0766855066 | E7: 178, P.Tân An,Ninh Kiều,Cần Thơ | F7: done | G7: done | H7: done | I7: done | J7: done all | K7: Cần Thơ | L7: A. Tho
A8: 7 | B8: Phạm Thị Mơ | C8: nhà thuốc Anh Tuấn | D8: 0986190286 | E8: 204 hồng mai, P.Quỳnh Lôi,Hai Bà Trưng,Hà Nội | F8: done | G8: done | H8: done | I8: done | J8: done all | K8: HN | L8: C. Quy
A9: 8 | B9: C Hằng | C9: NT Thanh Binh | D9: 0374635903 | E9: 14 Trần Nhân Tông, P.Nguyễn Du,Hai Bà Trưng,Hà Nội | F9: done | G9: done | H9: done | I9: done | J9: done all | K9: HN | L9: C. Quy
A10: 9 | B10: Ngô Thi Lâm Thuân | C10: NT BAO KHOI | D10: 0908412436 | E10: 702 HUONG LO 2, P. BINH TRI DONG A, P.Bình Hưng Hòa,Bình Tân,Hồ Chí Minh | F10: done | G10: done | H10: done | I10: done | J10: done all | K10: HCM | L10: A. Tri
A11: 10 | B11: Ngô thị Yến | C11: nhà thuốc Nguyễn thị kim liên | D11: 0398019788 | E11: Số 72 phố Trần Bình, P.Mai Dịch,Cầu Giấy,Hà Nội | F11: done | G11: done | H11: done | I11: done | J11: done all | K11: HN | L11: C. Quy
A12: 11 | B12: Âu Chí Kiên | C12: Nhà Thuốc Phương Thảo | D12: 0938980689 | E12: 08 lô C Mạc Thiên Tích , P.11,Quận 5,Hồ Chí Minh | F12: done | G12: done | H12: done | I12: done | J12: done all | K12: HCM | L12: A. Tri
A13: 12 | B13: Thái thị huệ | C13: nhà thuốc DS Vu Van Thu | D13: 0982600388 | E13: 81B xuân diệu, P.Quảng An,Tây Hồ,Hà Nội | F13: done | G13: done | H13: done | I13: done | J13: done all | K13: HN | L13: C. Quy
... A88: 87 | B88: huynh thi cam loan | C88: Nha Thuoc Hai Binh | D88: 0934087637 | E88: 257B Nguyen Bieu- P. 2, P.02,Quận 5,Hồ Chí Minh | F88: done | G88: done | H88: done | I88: done | J88: done all | K88: HCM | L88: A. Tri
A89: 88 | D89: 0967140666 | E89: 15 Yên Lạc, Hà Nội | F89: done | G89: done | H89: done | I89: done | J89: done all | K89: HN | L89: C. Quy
A90: 89 | D90: 0902213933 | E90: 70 Hồng Mai, Hà Nội | F90: done | G90: done | H90: done | I90: done | J90: done all | K90: HN | L90: C. Quy
A91: 90 | B91: Trần Thanh Thanh | C91: NHA THUOC PHUONG NHI | D91: 0903452774 | E91: 43A PHAN XÍCH LONG, PHƯỜNG 2, QUẬN PHÚ NHUẬN, TP.HCM, P.02,Phú Nhuận,Hồ Chí Minh | F91: done | G91: done | H91: done | I91: done | J91: done all | K91: HCM | L91: A. Tri
A92: 91 | B92: Nguyễn Thị Thẳng | C92: Nt anh tu | D92: 0379175142 | E92: 299 phan xich long p1 Q PN, P.01,Phú Nhuận,Hồ Chí Minh | F92: done | G92: done | H92: done | I92: done | J92: done all | K92: HCM | L92: A. Tri
A93: 92 | B93: Vnlocation8099 | C93: nt yen lac 19 | D93: 0942419868 | E93: 21 yen lac, P.Vĩnh Tuy,Hai Bà Trưng,Hà Nội | F93: done | G93: done | H93: done | I93: done | J93: done all | K93: HN | L93: C. Quy
